<?xml version="1.0" encoding="UTF-8"?>
<testng-results ignored="0" total="4" passed="1" failed="3" skipped="0">
  <reporter-output>
  </reporter-output>
  <suite started-at="2025-05-21T13:28:13 IST" name="Surefire suite" finished-at="2025-05-21T13:28:31 IST" duration-ms="17735">
    <groups>
    </groups>
    <test started-at="2025-05-21T13:28:13 IST" name="Surefire test" finished-at="2025-05-21T13:28:31 IST" duration-ms="17735">
      <class name="test.AddEmployeeTest">
        <test-method is-config="true" signature="setup()[pri:0, instance:test.AddEmployeeTest@1198b989]" started-at="2025-05-21T13:28:13 IST" name="setup" finished-at="2025-05-21T13:28:21 IST" duration-ms="7735" status="PASS">
          <reporter-output>
          </reporter-output>
        </test-method> <!-- setup -->
        <test-method signature="addEmployeeTest()[pri:0, instance:test.AddEmployeeTest@1198b989]" started-at="2025-05-21T13:28:21 IST" name="addEmployeeTest" finished-at="2025-05-21T13:28:28 IST" duration-ms="6804" status="FAIL">
          <exception class="java.lang.AssertionError">
            <message>
              <![CDATA[Employee was not added! expected [true] but found [false]]]>
            </message>
            <full-stacktrace>
              <![CDATA[java.lang.AssertionError: Employee was not added! expected [true] but found [false]
at org.testng.Assert.fail(Assert.java:111)
at org.testng.Assert.failNotEquals(Assert.java:1578)
at org.testng.Assert.assertTrue(Assert.java:57)
at test.AddEmployeeTest.addEmployeeTest(AddEmployeeTest.java:24)
at java.base/jdk.internal.reflect.DirectMethodHandleAccessor.invoke(DirectMethodHandleAccessor.java:103)
at java.base/java.lang.reflect.Method.invoke(Method.java:580)
at org.testng.internal.invokers.MethodInvocationHelper.invokeMethod(MethodInvocationHelper.java:139)
at org.testng.internal.invokers.TestInvoker.invokeMethod(TestInvoker.java:664)
at org.testng.internal.invokers.TestInvoker.invokeTestMethod(TestInvoker.java:228)
at org.testng.internal.invokers.MethodRunner.runInSequence(MethodRunner.java:63)
at org.testng.internal.invokers.TestInvoker$MethodInvocationAgent.invoke(TestInvoker.java:961)
at org.testng.internal.invokers.TestInvoker.invokeTestMethods(TestInvoker.java:201)
at org.testng.internal.invokers.TestMethodWorker.invokeTestMethods(TestMethodWorker.java:148)
at org.testng.internal.invokers.TestMethodWorker.run(TestMethodWorker.java:128)
at java.base/java.util.ArrayList.forEach(ArrayList.java:1596)
at org.testng.TestRunner.privateRun(TestRunner.java:819)
at org.testng.TestRunner.run(TestRunner.java:619)
at org.testng.SuiteRunner.runTest(SuiteRunner.java:443)
at org.testng.SuiteRunner.runSequentially(SuiteRunner.java:437)
at org.testng.SuiteRunner.privateRun(SuiteRunner.java:397)
at org.testng.SuiteRunner.run(SuiteRunner.java:336)
at org.testng.SuiteRunnerWorker.runSuite(SuiteRunnerWorker.java:52)
at org.testng.SuiteRunnerWorker.run(SuiteRunnerWorker.java:95)
at org.testng.TestNG.runSuitesSequentially(TestNG.java:1301)
at org.testng.TestNG.runSuitesLocally(TestNG.java:1228)
at org.testng.TestNG.runSuites(TestNG.java:1134)
at org.testng.TestNG.run(TestNG.java:1101)
at org.apache.maven.surefire.testng.TestNGExecutor.run(TestNGExecutor.java:155)
at org.apache.maven.surefire.testng.TestNGDirectoryTestSuite.executeMulti(TestNGDirectoryTestSuite.java:169)
at org.apache.maven.surefire.testng.TestNGDirectoryTestSuite.execute(TestNGDirectoryTestSuite.java:88)
at org.apache.maven.surefire.testng.TestNGProvider.invoke(TestNGProvider.java:137)
at org.apache.maven.surefire.booter.ForkedBooter.runSuitesInProcess(ForkedBooter.java:385)
at org.apache.maven.surefire.booter.ForkedBooter.execute(ForkedBooter.java:162)
at org.apache.maven.surefire.booter.ForkedBooter.run(ForkedBooter.java:507)
at org.apache.maven.surefire.booter.ForkedBooter.main(ForkedBooter.java:495)
]]>
            </full-stacktrace>
          </exception> <!-- java.lang.AssertionError -->
          <reporter-output>
          </reporter-output>
        </test-method> <!-- addEmployeeTest -->
        <test-method is-config="true" signature="tearDown()[pri:0, instance:test.AddEmployeeTest@1198b989]" started-at="2025-05-21T13:28:28 IST" name="tearDown" finished-at="2025-05-21T13:28:28 IST" duration-ms="274" status="PASS">
          <reporter-output>
          </reporter-output>
        </test-method> <!-- tearDown -->
      </class> <!-- test.AddEmployeeTest -->
      <class name="apiTest.ReqresApiTest">
        <test-method signature="testCreateUser()[pri:0, instance:apiTest.ReqresApiTest@4278a03f]" started-at="2025-05-21T13:28:28 IST" name="testCreateUser" finished-at="2025-05-21T13:28:30 IST" duration-ms="1838" status="FAIL">
          <exception class="java.lang.AssertionError">
            <message>
              <![CDATA[expected [201] but found [401]]]>
            </message>
            <full-stacktrace>
              <![CDATA[java.lang.AssertionError: expected [201] but found [401]
at org.testng.Assert.fail(Assert.java:111)
at org.testng.Assert.failNotEquals(Assert.java:1578)
at org.testng.Assert.assertEqualsImpl(Assert.java:150)
at org.testng.Assert.assertEquals(Assert.java:132)
at org.testng.Assert.assertEquals(Assert.java:1419)
at org.testng.Assert.assertEquals(Assert.java:1383)
at org.testng.Assert.assertEquals(Assert.java:1429)
at apiTest.ReqresApiTest.testCreateUser(ReqresApiTest.java:25)
at java.base/jdk.internal.reflect.DirectMethodHandleAccessor.invoke(DirectMethodHandleAccessor.java:103)
at java.base/java.lang.reflect.Method.invoke(Method.java:580)
at org.testng.internal.invokers.MethodInvocationHelper.invokeMethod(MethodInvocationHelper.java:139)
at org.testng.internal.invokers.TestInvoker.invokeMethod(TestInvoker.java:664)
at org.testng.internal.invokers.TestInvoker.invokeTestMethod(TestInvoker.java:228)
at org.testng.internal.invokers.MethodRunner.runInSequence(MethodRunner.java:63)
at org.testng.internal.invokers.TestInvoker$MethodInvocationAgent.invoke(TestInvoker.java:961)
at org.testng.internal.invokers.TestInvoker.invokeTestMethods(TestInvoker.java:201)
at org.testng.internal.invokers.TestMethodWorker.invokeTestMethods(TestMethodWorker.java:148)
at org.testng.internal.invokers.TestMethodWorker.run(TestMethodWorker.java:128)
at java.base/java.util.ArrayList.forEach(ArrayList.java:1596)
at org.testng.TestRunner.privateRun(TestRunner.java:819)
at org.testng.TestRunner.run(TestRunner.java:619)
at org.testng.SuiteRunner.runTest(SuiteRunner.java:443)
at org.testng.SuiteRunner.runSequentially(SuiteRunner.java:437)
at org.testng.SuiteRunner.privateRun(SuiteRunner.java:397)
at org.testng.SuiteRunner.run(SuiteRunner.java:336)
at org.testng.SuiteRunnerWorker.runSuite(SuiteRunnerWorker.java:52)
at org.testng.SuiteRunnerWorker.run(SuiteRunnerWorker.java:95)
at org.testng.TestNG.runSuitesSequentially(TestNG.java:1301)
at org.testng.TestNG.runSuitesLocally(TestNG.java:1228)
at org.testng.TestNG.runSuites(TestNG.java:1134)
at org.testng.TestNG.run(TestNG.java:1101)
at org.apache.maven.surefire.testng.TestNGExecutor.run(TestNGExecutor.java:155)
at org.apache.maven.surefire.testng.TestNGDirectoryTestSuite.executeMulti(TestNGDirectoryTestSuite.java:169)
at org.apache.maven.surefire.testng.TestNGDirectoryTestSuite.execute(TestNGDirectoryTestSuite.java:88)
at org.apache.maven.surefire.testng.TestNGProvider.invoke(TestNGProvider.java:137)
at org.apache.maven.surefire.booter.ForkedBooter.runSuitesInProcess(ForkedBooter.java:385)
at org.apache.maven.surefire.booter.ForkedBooter.execute(ForkedBooter.java:162)
at org.apache.maven.surefire.booter.ForkedBooter.run(ForkedBooter.java:507)
at org.apache.maven.surefire.booter.ForkedBooter.main(ForkedBooter.java:495)
]]>
            </full-stacktrace>
          </exception> <!-- java.lang.AssertionError -->
          <reporter-output>
          </reporter-output>
        </test-method> <!-- testCreateUser -->
        <test-method signature="testDeleteUser()[pri:0, instance:apiTest.ReqresApiTest@4278a03f]" started-at="2025-05-21T13:28:30 IST" name="testDeleteUser" finished-at="2025-05-21T13:28:30 IST" duration-ms="377" status="FAIL">
          <exception class="java.lang.AssertionError">
            <message>
              <![CDATA[expected [204] but found [401]]]>
            </message>
            <full-stacktrace>
              <![CDATA[java.lang.AssertionError: expected [204] but found [401]
at org.testng.Assert.fail(Assert.java:111)
at org.testng.Assert.failNotEquals(Assert.java:1578)
at org.testng.Assert.assertEqualsImpl(Assert.java:150)
at org.testng.Assert.assertEquals(Assert.java:132)
at org.testng.Assert.assertEquals(Assert.java:1419)
at org.testng.Assert.assertEquals(Assert.java:1383)
at org.testng.Assert.assertEquals(Assert.java:1429)
at apiTest.ReqresApiTest.testDeleteUser(ReqresApiTest.java:32)
at java.base/jdk.internal.reflect.DirectMethodHandleAccessor.invoke(DirectMethodHandleAccessor.java:103)
at java.base/java.lang.reflect.Method.invoke(Method.java:580)
at org.testng.internal.invokers.MethodInvocationHelper.invokeMethod(MethodInvocationHelper.java:139)
at org.testng.internal.invokers.TestInvoker.invokeMethod(TestInvoker.java:664)
at org.testng.internal.invokers.TestInvoker.invokeTestMethod(TestInvoker.java:228)
at org.testng.internal.invokers.MethodRunner.runInSequence(MethodRunner.java:63)
at org.testng.internal.invokers.TestInvoker$MethodInvocationAgent.invoke(TestInvoker.java:961)
at org.testng.internal.invokers.TestInvoker.invokeTestMethods(TestInvoker.java:201)
at org.testng.internal.invokers.TestMethodWorker.invokeTestMethods(TestMethodWorker.java:148)
at org.testng.internal.invokers.TestMethodWorker.run(TestMethodWorker.java:128)
at java.base/java.util.ArrayList.forEach(ArrayList.java:1596)
at org.testng.TestRunner.privateRun(TestRunner.java:819)
at org.testng.TestRunner.run(TestRunner.java:619)
at org.testng.SuiteRunner.runTest(SuiteRunner.java:443)
at org.testng.SuiteRunner.runSequentially(SuiteRunner.java:437)
at org.testng.SuiteRunner.privateRun(SuiteRunner.java:397)
at org.testng.SuiteRunner.run(SuiteRunner.java:336)
at org.testng.SuiteRunnerWorker.runSuite(SuiteRunnerWorker.java:52)
at org.testng.SuiteRunnerWorker.run(SuiteRunnerWorker.java:95)
at org.testng.TestNG.runSuitesSequentially(TestNG.java:1301)
at org.testng.TestNG.runSuitesLocally(TestNG.java:1228)
at org.testng.TestNG.runSuites(TestNG.java:1134)
at org.testng.TestNG.run(TestNG.java:1101)
at org.apache.maven.surefire.testng.TestNGExecutor.run(TestNGExecutor.java:155)
at org.apache.maven.surefire.testng.TestNGDirectoryTestSuite.executeMulti(TestNGDirectoryTestSuite.java:169)
at org.apache.maven.surefire.testng.TestNGDirectoryTestSuite.execute(TestNGDirectoryTestSuite.java:88)
at org.apache.maven.surefire.testng.TestNGProvider.invoke(TestNGProvider.java:137)
at org.apache.maven.surefire.booter.ForkedBooter.runSuitesInProcess(ForkedBooter.java:385)
at org.apache.maven.surefire.booter.ForkedBooter.execute(ForkedBooter.java:162)
at org.apache.maven.surefire.booter.ForkedBooter.run(ForkedBooter.java:507)
at org.apache.maven.surefire.booter.ForkedBooter.main(ForkedBooter.java:495)
]]>
            </full-stacktrace>
          </exception> <!-- java.lang.AssertionError -->
          <reporter-output>
          </reporter-output>
        </test-method> <!-- testDeleteUser -->
        <test-method signature="testGetUsers()[pri:0, instance:apiTest.ReqresApiTest@4278a03f]" started-at="2025-05-21T13:28:30 IST" name="testGetUsers" finished-at="2025-05-21T13:28:31 IST" duration-ms="663" status="PASS">
          <reporter-output>
          </reporter-output>
        </test-method> <!-- testGetUsers -->
      </class> <!-- apiTest.ReqresApiTest -->
    </test> <!-- Surefire test -->
  </suite> <!-- Surefire suite -->
</testng-results>
